#VRML_SIM R2023b utf8

EXTERNPROTO "https://raw.githubusercontent.com/cyberbotics/webots/R2023b/projects/objects/backgrounds/protos/TexturedBackground.proto"
EXTERNPROTO "https://raw.githubusercontent.com/cyberbotics/webots/R2023b/projects/objects/backgrounds/protos/TexturedBackgroundLight.proto"
EXTERNPROTO "https://raw.githubusercontent.com/cyberbotics/webots/R2023b/projects/objects/floors/protos/RectangleArena.proto"
EXTERNPROTO "https://raw.githubusercontent.com/cyberbotics/webots/R2023b/projects/objects/apartment_structure/protos/Wall.proto"
EXTERNPROTO "https://raw.githubusercontent.com/cyberbotics/webots/R2023b/projects/robots/gctronic/e-puck/protos/E-puck.proto"

WorldInfo {
}
Viewpoint {
  orientation -0.6012459993679776 0.31966313868280566 0.7323378496373509 2.3070246908994037
  position 1.4935483841632167 -0.12023028774728389 2.374414472832857
}
E-puck {
  hidden position_0_0 -1.641306427771101e-09
  hidden position_0_1 5.41294654354627
  hidden rotation_1 0 1 0 0.7677672763661115
  hidden rotation_2 0 1 0 6.256536987068902
  translation 1.29038 0.926442 -0.234624
  rotation 0.7377097954990451 -0.25695064636075976 0.6243081154042007 0.30380138950056856
  name "e-puck(1)"
  controller "pathfollow"
  supervisor TRUE
  turretSlot [
    Camera {
      translation 0 -0.01 -0.045
      name "camera1"
      recognitionColors [
        1 1 0
      ]
      fieldOfView 1.57
      width 80
      height 80
      recognition Recognition {
      }
    }
    DistanceSensor {
      translation 0.035 -0.01 -0.01
      name "right_ds"
      lookupTable [
        0 0 0
        1.27 1.27 0
      ]
    }
    DistanceSensor {
      translation -0.035 -0.01 -0.01
      rotation 0 1 0 3.14
      name "left_ds"
      lookupTable [
        0 0 0
        1.27 1.27 0
      ]
    }
    DistanceSensor {
      translation 0 0 -0.045
      rotation 0 1 0 1.57
      name "front_ds"
      recognitionColors [
        0 0 0
      ]
      lookupTable [
        0 0 0
        1.27 1.27 0
      ]
    }
    DEF lefthinge HingeJoint {
      jointParameters HingeJointParameters {
        position -2.6531929542272792e-08
        axis -1 0 0
        anchor 0 0.025 0
      }
      device [
        PositionSensor {
          name "left wheel sensor"
        }
        RotationalMotor {
          name "left wheel motor"
          consumptionFactor 70
          controlPID 8 0 0
        }
      ]
      endPoint Solid {
        translation -0.04500000000000003 0.025000000001061277 -4.000000000000008e-05
        rotation -0.9999982136902201 0.0004729991395881597 0.001829996771333231 1.2399999734681133
        children [
          DEF WHEEL Pose {
            translation 0.007 0 -0.05
            rotation 0 0 1 1.57
            children [
              Shape {
                appearance PBRAppearance {
                  baseColor 0.1 0.1 0.1
                  transparency 1
                  roughness 1
                  metalness 0
                }
                geometry Cylinder {
                  height 0.01
                  radius 0.02
                }
              }
            ]
            rotationStep 0.25
          }
        ]
        name "left wheel(1)"
        boundingObject USE WHEEL
        physics DEF PHYSICS_WHEEL Physics {
        }
      }
    }
    DEF righthinge HingeJoint {
      jointParameters HingeJointParameters {
        position 5.411353892574481
        axis -1 0 0
        anchor 0 0.025 0
      }
      device [
        PositionSensor {
          name "right wheel sensor"
        }
        RotationalMotor {
          name "left wheel motor"
          consumptionFactor 70
          controlPID 8 2 0.5
        }
      ]
      endPoint Solid {
        translation 0.045 0.025030620343972486 -2.5737026537788085e-05
        rotation 0.9999993190153901 0.0006639349856596728 -0.0009597703323466746 5.511831119156308
        children [
          DEF WHEEL Pose {
            translation -0.007 0.01 -0.05
            rotation 0 0 1 1.57
            children [
              Shape {
                appearance PBRAppearance {
                  baseColor 0 0 0
                  transparency 1
                  roughness 1
                  metalness 0
                }
                geometry Cylinder {
                  height 0.01
                  radius 0.02
                }
              }
            ]
            rotationStep 0.25
          }
        ]
        name "right wheel(1)"
        boundingObject USE WHEEL
        physics DEF PHYSICS_WHEEL Physics {
        }
        rotationStep 0.25
      }
    }
    InertialUnit {
      rotation 0 1 0 3.14
    }
  ]
}
TexturedBackground {
}
TexturedBackgroundLight {
}
RectangleArena {
  translation 0.0303838 -0.522541 -0.24
  name "rectangle arena(5)"
  floorSize 3.5 3.6
}
Wall {
  translation -1.22271 -1.07333 6.77236e-14
  rotation 0 1 0 1.57
  name "wall(17)"
  size 0.5 0.5 0.001
}
Wall {
  translation -0.215988 0.430243 4.44089e-16
  rotation 0 1 0 1.57
  name "wall(19)"
  size 0.5 0.5 0.001
}
Wall {
  translation -0.72058 -1.07009 6.43929e-14
  rotation 0 1 0 1.57
  name "wall(16)"
  size 0.5 0.5 0.001
}
Wall {
  translation -0.72054 -0.571387 7.32748e-15
  rotation 0 1 0 1.57
  name "wall(18)"
  size 0.5 0.5 0.001
}
Wall {
  translation -0.724259 0.929644 4.44089e-16
  rotation 0 1 0 1.57
  name "wall(15)"
  size 0.5 0.5 0.001
}
Wall {
  translation -0.718108 0.177582 9.32586e-15
  rotation 1 0 0 1.57
  name "wall(1)"
  size 1 0.5 0.001
}
Wall {
  translation -0.191726 1.17694 1.0214e-14
  rotation 1 0 0 1.57
  name "wall(28)"
  size 3 0.5 0.001
}
Wall {
  translation 0.201132 -2.3195 -2.26486e-14
  rotation 1 0 0 1.57
  name "wall(31)"
  size 3 0.5 0.001
}
Wall {
  translation 0.0288631 0.1819 -8.4377e-15
  rotation 1 0 0 1.57
  name "wall(24)"
  size 0.5 0.5 0.001
}
Wall {
  translation 1.02855 -0.322388 -8.88177e-16
  rotation 1 0 0 1.57
  name "wall(13)"
  size 0.5 0.5 0.001
}
Wall {
  translation -0.472587 -1.3187 2.37588e-14
  rotation 1 0 0 1.57
  name "wall(9)"
  size 0.5 0.5 0.001
}
Wall {
  translation -0.973699 -0.822108 3.73035e-14
  rotation 1 0 0 1.57
  name "wall(21)"
  size 0.5 0.5 0.001
}
Wall {
  translation -0.971384 0.679958 2.22046e-16
  rotation 1 0 0 1.57
  name "wall(23)"
  size 0.5 0.5 0.001
}
Wall {
  translation -0.967797 -0.322109 3.77476e-15
  rotation 1 0 0 1.57
  name "wall(27)"
  size 0.5 0.5 0.001
}
Wall {
  translation -0.46901 -0.824803 4.44088e-15
  rotation 1 0 0 1.57
  name "wall(20)"
  size 0.5 0.5 0.001
}
Wall {
  translation 0.532422 -1.32107 -6.4393e-15
  rotation 1 0 0 1.57
  name "wall(22)"
  size 0.5 0.5 0.001
}
Wall {
  translation 0.0350785 0.678525 2.44248e-15
  rotation 1 0 0 1.57
  name "wall(10)"
  size 0.5 0.5 0.001
}
Wall {
  translation 1.02866 0.182207 9.10382e-15
  rotation 1 0 0 1.57
  name "wall(25)"
  size 0.5 0.5 0.001
}
Wall {
  translation 1.54246 1.18063 7.9936e-15
  rotation 1 0 0 1.57
  name "wall(12)"
  size 0.5 0.5 0.001
}
Wall {
  translation 0.530047 0.181858 2.33146e-15
  rotation 1 0 0 1.57
  name "wall(26)"
  size 0.5 0.5 0.001
}
Wall {
  translation 1.02795 -0.821551 -1.9984e-15
  rotation 1 0 0 1.57
  name "wall(4)"
  size 0.5 0.5 0.001
}
Wall {
  translation 1.52818 -1.31875 -2.46469e-14
  rotation 1 0 0 1.57
  name "wall(8)"
  size 0.5 0.5 0.001
}
Wall {
  translation 0.031153 -0.321965 -1.55431e-15
  rotation 1 0 0 1.57
  name "wall(3)"
  size 0.5 0.5 0.001
}
Wall {
  translation 1.27874 0.430463 1.22124e-15
  rotation 0 1 0 1.57
  name "wall(6)"
  size 0.5 0.5 0.001
}
Wall {
  translation 1.77816 0.92349 3.44169e-15
  rotation 0 1 0 1.57
  name "wall(2)"
  size 0.5 0.5 0.001
}
Wall {
  translation 0.781941 0.433238 4.44089e-16
  rotation 0 1 0 1.57
  name "wall(14)"
  size 0.5 0.5 0.001
}
Wall {
  translation 0.780216 -0.571935 2.22044e-16
  rotation 0 1 0 1.57
  name "wall(11)"
  size 0.5 0.5 0.001
}
Wall {
  translation 1.28207 -1.06985 1.11022e-15
  rotation 0 1 0 1.57
  name "wall(7)"
  size 0.5 0.5 0.001
}
Wall {
  translation -1.69074 -0.0691106 1.44329e-14
  rotation 0 1 0 1.57
  name "wall(5)"
  size 0.5 2.5 0.001
}
Wall {
  translation 1.77564 -0.825217 1.90959e-14
  rotation 0 1 0 1.57
  name "wall(30)"
  size 0.5 3 0.001
}
Wall {
  translation 0.284959 -0.322624 -6.66134e-16
  rotation 0 1 0 1.57
  name "wall(29)"
  size 0.5 1 0.001
}
DEF epuck E-puck {
  hidden position_0_0 -9.959606845002733e-11
  hidden position_0_1 -1.1422610380929031e-10
  hidden translation_1 0 0.026000000000000016 0.02
  hidden rotation_1 0 -1 0 5.960464477539063e-08
  hidden translation_2 0 -0.025999999999999936 0.02
  hidden rotation_2 0 1 0 0
  translation 1.627400010449133 1.0379000148076856 -0.2400701940004544
  rotation 0.17956210488624277 -0.9837465043460789 0.0005154373796760341 0.0015153105663553107
  controller "<generic>"
  turretSlot [
    InertialUnit {
      rotation 0 1 0 3.14
    }
    DEF righthinge HingeJoint {
      jointParameters HingeJointParameters {
        position -7.423621842037199e-09
        axis -1 0 0
        anchor 0 0.025 0
      }
      device [
        PositionSensor {
          name "right wheel sensor"
        }
        RotationalMotor {
          name "left wheel motor"
          consumptionFactor 70
          controlPID 8 2 0.5
        }
      ]
      endPoint Solid {
        translation 0.045 0.025000000000296948 -4.000000000000006e-05
        rotation -0.9999998202590471 -0.00010099998438853537 0.0005909998954385684 1.643185299755964
        children [
          DEF WHEEL Pose {
            translation -0.007 0.01 -0.05
            rotation 0 0 1 1.57
            children [
              Shape {
                appearance PBRAppearance {
                  baseColor 0 0 0
                  transparency 1
                  roughness 1
                  metalness 0
                }
                geometry Cylinder {
                  height 0.01
                  radius 0.02
                }
              }
            ]
            rotationStep 0.25
          }
        ]
        name "right wheel(1)"
        boundingObject USE WHEEL
        physics DEF PHYSICS_WHEEL Physics {
        }
        rotationStep 0.25
      }
    }
    DEF lefthinge HingeJoint {
      jointParameters HingeJointParameters {
        position -3.5145163346242317e-08
        axis -1 0 0
        anchor 0 0.025 0
      }
      device [
        PositionSensor {
          name "left wheel sensor"
        }
        RotationalMotor {
          name "left wheel motor"
          consumptionFactor 70
          controlPID 8 0 0
        }
      ]
      endPoint Solid {
        translation -0.04500000000000003 0.025000000001405807 -4.0000000000000064e-05
        rotation -0.9999982136901984 0.0004729991345604009 0.0018299967844095924 1.2399999648548947
        children [
          DEF WHEEL Pose {
            translation 0.007 0 -0.05
            rotation 0 0 1 1.57
            children [
              Shape {
                appearance PBRAppearance {
                  baseColor 0.1 0.1 0.1
                  transparency 1
                  roughness 1
                  metalness 0
                }
                geometry Cylinder {
                  height 0.01
                  radius 0.02
                }
              }
            ]
            rotationStep 0.25
          }
        ]
        name "left wheel(1)"
        boundingObject USE WHEEL
        physics DEF PHYSICS_WHEEL Physics {
        }
      }
    }
    DistanceSensor {
      translation 0 0 -0.045
      rotation 0 1 0 1.57
      name "front_ds"
      recognitionColors [
        0 0 0
      ]
      lookupTable [
        0 0 0
        1.27 1.27 0
      ]
    }
    DistanceSensor {
      translation 0.035 -0.01 -0.01
      name "right_ds"
      lookupTable [
        0 0 0
        1.27 1.27 0
      ]
    }
    DistanceSensor {
      translation -0.035 -0.01 -0.01
      rotation 0 1 0 3.14
      name "left_ds"
      lookupTable [
        0 0 0
        1.27 1.27 0
      ]
    }
    Camera {
      translation 0 -0.01 -0.045
      name "camera1"
      recognitionColors [
        1 1 0
      ]
      fieldOfView 1.57
      width 80
      height 80
      recognition Recognition {
      }
    }
  ]
}
